<?xml version='1.0' encoding='utf-8'?>
<robot xmlns:xacro="http://www.ros.org/wiki/xacro" name="housem8">
    
    <!-- <link name="world">
    </link>

    <link name="map">
    </link>

    <link name="odom">
    </link>

    <link name="imu_link">
    </link> -->

    <link name="base_footprint">
        <pose> 0 0 0 0 0 0</pose>
    </link>

    <link name="mobilebaseI">
        <visual name="mobilebaseI">
            <geometry name = "mobilebaseI">
                <box size="0.200 0.240 0.160"/>
                <origin xyz="0.0 0.0 0.180" rpy="0.0 0.0 0.0"/>
            </geometry>
        </visual>
        <inertial>
            <mass value="20.0"/>
            <inertia ixx="5.0" ixy="0.0" ixz="0.0" 
                     iyy="7.0" iyz="0.0" izz="6.0"/>
        </inertial>
        <collision>
            <origin xyz="0.0 0.0 0.180" rpy="0.0 0.0 0.0"/>
            <geometry name = "mobilebaseI">
                <box size="0.200 0.240 0.160"/>
                
            </geometry>
        </collision>
    </link>

    <!-- <joint name="world_to_map" type="fixed">
        <parent link="world"/>
        <child link="map"/>
        <origin rpy="0 0 0" xyz="0 0 0"/>
    </joint>

    <joint name="map_to_odom" type="fixed">
        <parent link="map"/>
        <child link="odom"/>
        <origin rpy="0 0 0" xyz="0 0 0"/>
    </joint>

    <joint name="odom_to_imu" type="fixed">
        <parent link="odom"/>
        <child link="imu_link"/>
        <origin rpy="0 0 0" xyz="0 0 0"/>
    </joint>

    <joint name="imu_to_basefootprint" type="fixed">
        <parent link="imu_link"/>
        <child link="base_footprint"/>
        <origin rpy="0 0 0" xyz="0 0 0"/>
    </joint>

    <joint name="basefootprint_to_baselink" type="fixed">
        <origin xyz="0 0 0.1" rpy="0 0 0"/>
        <parent link="base_footprint"/>
        <child link="mobilebaseI"/>
    </joint> -->

    <!-- <joint name="world_to_base" type="fixed">
        <parent link="world"/>
        <child link="mobilebaseI"/>
        <origin rpy="0 0 0" xyz="0 0 0.1"/>
    </joint> -->

    <joint name="basefootprint_to_base" type="fixed">
        <parent link="base_footprint"/>
        <child link="mobilebaseI"/>
        <origin rpy="0 0 0" xyz="0 0 0.1"/>
    </joint>

    <link name="mobilebaseII">
        <visual name="mobilebaseII">
            <geometry name = "mobilebaseII">
                <box size="0.270 0.400 0.100"/>
                <origin xyz="0.0 0.0 0.00" rpy="0.0 0.0 0.0"/>
            </geometry>
            <!-- <material name="white">
            </material> -->
        </visual>
        <inertial>
            <mass value="18.0"/>
            <inertia ixx="8.0" ixy="0.0" ixz="0.0" 
                     iyy="2.0" iyz="0.0" izz="1.0"/>
        </inertial>
        <collision>
            <origin xyz="0.0 0.0 0.00" rpy="0.0 0.0 0.0"/>
            <geometry name = "mobilebaseII">
                <box size="0.270 0.400 0.100"/>
                
            </geometry>
        </collision>
    </link>

    <joint name="MobileBaseWheel" type="fixed">
        <origin xyz="0.235 0.0 0.110" rpy="0.0 0.0 0.0"/>
        <parent link="mobilebaseI"/>
        <child link="mobilebaseII"/>
    </joint>

    <link name="Wheel_Right">
        <inertial>
            <mass value="1.5"/>
            <inertia ixx="8.0" ixy="0.0" ixz="0.0" 
                     iyy="4.0" iyz="0.0" izz="4.0"/>
        </inertial>
        <visual name="Wheel">
            <origin xyz="0.0 0.0 0.0" rpy="0.0 0.0 0.0"/>
            <geometry name = "wheel">
                <cylinder radius="0.100" length="0.070"/>
            </geometry>
            <!-- <material name="Gray1">
                <color rgba="0.7 0.7 0.7 1.0"/>
            </material> -->
        </visual>
        <collision>
            <origin xyz="0.0 0.0 0.0" rpy="0.0 0.0 0.0"/>
            <geometry name = "wheel">
                <cylinder radius="0.100" length="0.070"/>
                
            </geometry>
        </collision>
    </link>

    <joint name="wheel_right_joint" type="continuous">
        <origin xyz="0.0 0.155 0.005" rpy="1.57 0.0 0.0"/>
        <parent link="mobilebaseI"/>
        <child link="Wheel_Right"/>
        <axis xyz="0 0 1"/>
    </joint>

    <link name="Wheel_Left">
        <inertial>
            <mass value="1.5"/>
            <inertia ixx="8.0" ixy="0.0" ixz="0.0" 
                     iyy="4.0" iyz="0.0" izz="4.0"/>
        </inertial>
        <visual name="Wheel">
            <origin xyz="0.0 0.0 0.0" rpy="0.0 0.0 0.0"/>
            <geometry name = "wheel">
                <cylinder radius="0.100" length="0.070"/>
            </geometry>
            <!-- <material name="Gray1">
                <color rgba="0.7 0.7 0.7 1.0"/>
            </material> -->
        </visual>
        <collision>
            <origin xyz="0.0 0.0 0.0" rpy="0.0 0.0 0.0"/>
            <geometry name = "wheel">
                <cylinder radius="0.100" length="0.070"/>
                
            </geometry>
        </collision>
    </link>

    <joint name="wheel_left_joint" type="continuous">
        <origin xyz="0.0 -0.155 0.005" rpy="1.57 0.0 0.0"/>
        <parent link="mobilebaseI"/>
        <child link="Wheel_Left"/>
        <axis xyz="0 0 1"/>
    </joint>
    
    <link name="CasterCase_Left">
        <inertial>
            <mass value="0.06"/>
            <inertia ixx="0.2" ixy="0.0" ixz="0.0" 
                     iyy="0.6" iyz="-0.7" izz="0.2"/>
        </inertial>
        <visual name="CasterCase">
            <origin xyz="0.0 0.0 -0.005" rpy="0.0 0.0 0.0"/>
            <geometry name = "CasterC">
                <cylinder radius="0.025" length="0.010"/>
            </geometry>
        </visual>
        <collision>
            <origin xyz="0.0 0.0 -0.005" rpy="0.0 0.0 0.0"/>
            <geometry name = "CasterC">
                <cylinder radius="0.025" length="0.010"/>
            </geometry>
            <!-- <surface>
                <friction>
                  <ode>
                    <mu>1</mu>
                    <mu2>1</mu2>
                    <slip1>0</slip1>
                    <slip2>0</slip2>
                  </ode>
                </friction>
                <contact>
                  <ode>
                    <soft_cfm>0</soft_cfm>
                    <soft_erp>0.2</soft_erp>
                    <kp>1e+13</kp>
                    <kd>1</kd>
                    <max_vel>0.01</max_vel>
                    <min_depth>0</min_depth>
                  </ode>
                </contact>
              </surface> -->
        </collision>
    </link>

    <joint name="CasterCL" type="fixed">
        <origin xyz="0.040 -0.110 -0.05" rpy="0.0 0.0 0.0"/>
        <parent link="mobilebaseII"/>
        <child link="CasterCase_Left"/>
        <axis xyz="0 0 1"/>
    </joint>

    <link name="CasterWheel_Left">
        <inertial>
            <mass value="0.3"/>
            <inertia ixx="0.6" ixy="0.0" ixz="0.0" 
                     iyy="0.3" iyz="0.0" izz="0.3"/>
        </inertial>
        <visual name="CasterWheel">
            <origin xyz="0.0 0.0 0.0" rpy="0.0 0.0 0.0"/>
            <geometry name = "Casterwheel">
                <cylinder radius="0.0625" length="0.036"/>
            </geometry>
        </visual>
        <collision>
            <origin xyz="0.0 0.0 0.0" rpy="0.0 0.0 0.0"/>
            <geometry name = "Casterwheel">
                <cylinder radius="0.0625" length="0.036"/>
                
            </geometry>
        </collision>
    </link>

    <joint name="Casterwheel_left_joint" type="continuous">
        <origin xyz="0.0405 0.0 -0.0925" rpy="1.57 0.0 0.0"/>
        <parent link="CasterCase_Left"/>
        <child link="CasterWheel_Left"/>
        <axis xyz="0 0 1"/>
        <!-- <dynamics damping="0.5" friction="0.2"/> -->
    </joint>

    <link name="CasterCase_Right">
        <inertial>
            <mass value="0.06"/>
            <inertia ixx="0.2" ixy="0.0" ixz="0.0" 
                     iyy="0.6" iyz="-0.7" izz="0.2"/>
        </inertial>
        <visual name="CasterCase">
            <origin xyz="0.0 0.0 -0.005" rpy="0.0 0.0 0.0"/>
            <geometry name = "CasterC">
                <cylinder radius="0.025" length="0.010"/>
            </geometry>
        </visual>
        <collision>
            <origin xyz="0.0 0.0 -0.005" rpy="0.0 0.0 0.0"/>
            <geometry name = "CasterC">
                <cylinder radius="0.025" length="0.010"/>
            </geometry>
            <surface>
                <friction>
                  <ode>
                    <mu>1</mu>
                    <mu2>1</mu2>
                    <slip1>0</slip1>
                    <slip2>0</slip2>
                  </ode>
                </friction>
                <contact>
                  <ode>
                    <soft_cfm>0</soft_cfm>
                    <soft_erp>0.2</soft_erp>
                    <kp>1e+13</kp>
                    <kd>1</kd>
                    <max_vel>0.01</max_vel>
                    <min_depth>0</min_depth>
                  </ode>
                </contact>
              </surface>
        </collision>
    </link>

    <joint name="CasterCR" type="fixed">
        <origin xyz="0.040 0.110 -0.05" rpy="0.0 0.0 0.0"/>
        <parent link="mobilebaseII"/>
        <child link="CasterCase_Right"/>
        <axis xyz="1.0 0.0 0.0"/>
        
    </joint>

    <link name="CasterWheel_Right">
        <inertial>
            <mass value="0.3"/>
            <inertia ixx="0.6" ixy="0.0" ixz="0.0" 
                     iyy="0.3" iyz="0.0" izz="0.3"/>
        </inertial>
        <visual name="CasterWheel">
            <origin xyz="0.0 0.0 0.0" rpy="0.0 0.0 0.0"/>
            <geometry name = "Casterwheel">
                <cylinder radius="0.0625" length="0.036"/>
            </geometry>
        </visual>
        <collision>
            <origin xyz="0.0 0.0 0.0" rpy="0.0 0.0 0.0"/>
            <geometry name = "Casterwheel">
                <cylinder radius="0.0625" length="0.036"/>
            </geometry>
        </collision>
    </link>

    <joint name="Casterwheel_right_joint" type="continuous">
        <origin xyz="0.0405 0.0 -0.0925" rpy="1.57 0.0 0.0"/>
        <parent link="CasterCase_Right"/>
        <child link="CasterWheel_Right"/>
        <axis xyz="0 0 1"/>
        <!-- <dynamics damping="0.5" friction="0.2"/> -->
    </joint>

    <link name="mobilebaseIII">
        <inertial>
            <mass value="20.0"/>
            <inertia ixx="0.6" ixy="0.0" ixz="0.0" 
                     iyy="0.1" iyz="0.0" izz="0.4"/>
        </inertial>
        <visual name = "mobilebaseIII">
            <origin xyz="0.0 0.0 0.0" rpy="0.0 0.0 0.0"/>
            <geometry name = "mobilebaseIII">
                <box size="0.235 0.180 0.030"/>
            </geometry >
            <!-- <material name="white"></material> -->
        </visual>
        <collision>
            <origin xyz="0.0 0.0 0.0" rpy="0.0 0.0 0.0"/>
            <geometry name = "mobilebaseIII">
                <box size="0.235 0.180 0.030"/>
            </geometry >
        </collision>
    </link>

    <joint name="MobileBaseLidar" type="fixed">     
        <origin xyz="-0.100 0.0 0.065" rpy="0.0 0.0 0.0"/>
        <parent link="mobilebaseII"/>
        <child link="mobilebaseIII"/>
        <axis xyz="0 0 1"/>
    </joint>

    <link name="mobilebaseIV">
        <inertial>
            <mass value="5.0"/>
            <inertia ixx="0.2" ixy="0.0" ixz="0.0" 
                     iyy="0.3" iyz="0.0" izz="0.1"/>
        </inertial>
        <visual name = "mobilebaseIII">
            <origin xyz="0.0 0.0 0.0" rpy="0.0 0.0 0.0"/>
            <geometry name = "mobilebaseIV">
                <box size="0.470 0.400 0.045"/>
            </geometry >
        </visual>
        <!-- <collision>
            <origin xyz="0.0 0.0 0.0" rpy="0.0 0.0 0.0"/>
            <geometry name = "mobilebaseIV">
                <box size="0.470 0.400 0.045"/>
            </geometry >
        </collision> -->
    </link>

    <joint name="MobileBaseTorsol" type="fixed">
        <origin xyz="0.0 0.0 0.0375" rpy="0.0 0.0 0.0"/>
        <parent link="mobilebaseIII"/>
        <child link="mobilebaseIV"/>
    </joint>

    <link name="Lidar_Front">
        <inertial>
            <mass value="0.3"/>
            <inertia ixx="0.4" ixy="0.0" ixz="0.0" 
                     iyy="0.7" iyz="0.0" izz="0.4"/>
        </inertial>
        <visual name="Lidar_Front">
            <origin xyz="0.0 0.0 0.0" rpy="0.0 0.0 0.0"/>
            <geometry name = "Lidar_front">
                <cylinder radius="0.035" length="0.030"/>
            </geometry>
            <!-- <material name="Gray4">
                <color rgba="0.2 0.2 0.2 1.0"/>
            </material> -->
        </visual>
        <collision>
            <origin xyz="0.0 0.0 0.0" rpy="0.0 0.0 0.0"/>
            <geometry name = "Lidar_front">
                <cylinder radius="0.035" length="0.030"/>
                
            </geometry>
        </collision>
    </link>

    <joint name="LidarF" type="fixed">
        <origin xyz="-0.178 0.150 0.0" rpy="0.0 0.0 3.14"/>
        <parent link="mobilebaseIII"/>
        <child link="Lidar_Front"/>
        <axis xyz="1.0 0.0 0.0"/>
    </joint>

    <link name="Lidar_Back">
        <inertial>
            <mass value="0.3"/>
            <inertia ixx="0.4" ixy="0.0" ixz="0.0" 
                     iyy="0.7" iyz="0.0" izz="0.4"/>
        </inertial>
        <visual name="Lidar_Back">
            <origin xyz="0.0 0.0 0.0" rpy="0.0 0.0 0.0"/>
            <geometry name = "Lidar_back">
                <cylinder radius="0.035" length="0.030"/>
            </geometry>
        </visual>
        <collision>
            <origin xyz="0.0 0.0 0.0" rpy="0.0 0.0 0.0"/>
            <geometry name = "Lidar_back">
                <cylinder radius="0.035" length="0.030"/>
                
            </geometry>
        </collision>
    </link>

    <joint name="LidarB" type="fixed">
        <origin xyz="0.178 -0.150 0.0" rpy="0.0 0.0 0.0"/>
        <parent link="mobilebaseIII"/>
        <child link="Lidar_Back"/>
        <axis xyz="1.0 0.0 0.0"/>
    </joint>

    <link name="Torsol">
        <inertial>
            <mass value="0.8"/>
            <inertia ixx="7.0" ixy="5.0" ixz="8.0" 
                     iyy="4.0" iyz="4.0" izz="7.0"/>
        </inertial>
        <visual name="Body">
            <origin xyz="0.0 0.0 0.445" rpy="0.0 0.0 0.0"/>
            <geometry name = "body">
                <box size="0.220 0.285 0.890"/>
            </geometry>
            <!-- <material name="white"></material> -->
        </visual>
        <collision>
            <origin xyz="0.125 0.0 0.445" rpy="0.0 0.0 0.0"/>
            <geometry name = "body">
                <box size="0.220 0.285 0.890"/>
                
            </geometry>
        </collision>
    </link>

    <joint name="BaseTorsol" type="fixed">
        <origin xyz="0.125 -0.0575 0.0225" rpy="0.0 0.0 0.0"/>
        <parent link="mobilebaseIV"/>
        <child link="Torsol"/>
    </joint>

    <link name="TorsolCamera">
        <inertial>
            <mass value="0.2"/>
            <inertia ixx="0.6" ixy="0.0" ixz="0.0" 
                     iyy="0.1" iyz="0.0" izz="0.1"/>
        </inertial>
        <visual name="Camera">
            <origin xyz="0.0 0.0 0.89" rpy="0.0 0.0 0.0"/>
            <geometry name = "Camera">
                <box size="0.03 0.08 0.03"/>
            </geometry>
            <material name="black"></material>
        </visual>
        <collision>
            <geometry name = "Camera">
                <box size="0.03 0.08 0.03"/>
            </geometry>
        </collision>
    </link>

    <joint name="BodyCam" type="revolute">
        <origin xyz="0.0 -0.16 0.0075" rpy="0.0 0.0 0.0"/>
        <parent link="mobilebaseIV"/>
        <child link="TorsolCamera"/>
        <axis xyz="0.0 1.0 0.0"/>
        <limit effort="1000.0" lower="-1.ค" upper="1.8" velocity="0.5"/>
    </joint>


    <link name="LinearJoint">
        <inertial>
            <mass value="0.5"/>
            <inertia ixx="7.0" ixy="-5.0" ixz="8.0" 
                     iyy="4.0" iyz="4.0" izz="7.0"/>
        </inertial>
        <visual>
            <origin xyz="0.0 0.0 0.0" rpy="0.0 0.0 0.0"/>
            <geometry name = "LinearJoint">
                <cylinder radius="0.080" length="0.050"/>
            </geometry>
        </visual>
        <collision>
            <origin xyz="0.0 0.0 0.0" rpy="0.0 0.0 0.0"/>
            <geometry name = "LinearJoint">
                <cylinder radius="0.080" length="0.050"/>
                
            </geometry>
        </collision>
    </link>

    <joint name="Mani_J0" type="prismatic">
        <origin xyz="0.0 0.0 0.0275" rpy="0.0 0.0 0.0"/>
        <parent link="mobilebaseIV"/>
        <child link="LinearJoint"/>
        <axis xyz="0 0 1"/>
        <limit lower="0.0" upper="0.650" effort="87.0" velocity="2.15"/>
        <dynamics damping="0.5" friction="0.2"/>
    </joint>

    <link name="Revlink1">
        <inertial>
            <mass value="0.1"/>
            <inertia ixx="0.4" ixy="0.0" ixz="0.0" 
                     iyy="0.4" iyz="0.7" izz="0.1"/>
        </inertial>
        <visual >
            <origin xyz="0.0 0.0 -0.050" rpy="0.0 0.0 0.0"/>
            <geometry name="Revlink1">
                <box size="0.080 0.080 0.100"/>
            </geometry>
        </visual>

          
        <collision>
            <origin xyz="0.0 0.0 -0.050" rpy="0.0 0.0 0.0"/>
            <geometry name="Revlink1">
                <box size="0.080 0.080 0.100"/>
               
            </geometry>
        </collision>
    </link>

    <joint name="Mani_J1" type="revolute">
        <origin xyz="0.0 0.0 0.125" rpy="0.0 0.0 0.0"/>
        <parent link="LinearJoint"/>
        <child link="Revlink1"/>
        <axis xyz="0 0 1"/>
        <limit effort="87" lower="-2.8973" upper="2.8973" velocity="2.1750"/>
        <dynamics damping="0.5" friction="0.2"/>
    </joint>

    <link name="Revlink2">
        <inertial>
            <mass value="0.1"/>
            <inertia ixx="0.9" ixy="0.0" ixz="0.0" 
                     iyy="0.4" iyz="0.0" izz="0.9"/>
        </inertial>
        <visual >
            <origin xyz="0.0 0.0 -0.050" rpy="0.0 0.0 0.0"/>
            <geometry name="Revlink2">
                <box size="0.080 0.080 0.100"/>
            </geometry>
        </visual>

        <collision>
            <origin xyz="0.0 0.0 -0.050" rpy="0.0 0.0 0.0"/>
            <geometry name="Revlink2">
                <box size="0.080 0.080 0.100"/>
                
            </geometry>
        </collision>
    </link>

    <joint name="Mani_J2" type="revolute">
        <origin xyz="0.0 0.0 0.100" rpy="0.0 0.0 0.0"/>
        <parent link="Revlink1"/>
        <child link="Revlink2"/>
        <axis xyz="1 0 0"/>
        <limit effort="87" lower="-2.8973" upper="2.8973" velocity="2.1750"/>
        <dynamics damping="0.5" friction="0.2"/>
    </joint>

    <link name="Revlink3">
        <inertial>
            <mass value="0.1"/>
            <inertia ixx="0.9" ixy="0.0" ixz="0.0" 
                     iyy="0.1" iyz="0.5" izz="0.8"/>
        </inertial>
        <visual >
            <origin xyz="-0.175 0.0 0.0" rpy="0.0 1.57 0.0"/>
            <geometry name="Revlink3">
                <box size="0.080 0.080 0.350"/>
            </geometry>
        </visual>



        <collision>
            <origin xyz="-0.175 0.0 0.0" rpy="0.0 1.57 0.0"/>
            <geometry name="Revlink3">
                <box size="0.080 0.080 0.350"/>
            </geometry>
        </collision>
    </link>

    <joint name="Mani_J3" type="revolute">
        <origin xyz="0.0 0.0 0.0" rpy="0.0 0.0 0.0"/>
        <parent link="Revlink2"/>
        <child link="Revlink3"/>
        <axis xyz="0 1 0"/>
        <limit effort="87" lower="-2.8973" upper="2.8973" velocity="2.1750"/>
        <dynamics damping="0.5" friction="0.2"/>
    </joint>

    <link name="Revlink4">
        <inertial>
            <mass value="0.1"/>
            <inertia ixx="0.9" ixy="0.0" ixz="0.0" 
                     iyy="0.1" iyz="0.5" izz="0.8"/>
        </inertial>
        <visual >
            <origin xyz="-0.175 0.0 0.0" rpy="0.0 1.57 0.0"/>
            <geometry name="Revlink4">
                <box size="0.080 0.080 0.350"/>
            </geometry>
        </visual>



        <collision>
            <origin xyz="-0.175 0.0 0.0" rpy="0.0 1.57 0.0"/>
            <geometry name="Revlink4">
                <box size="0.080 0.080 0.350"/>
                
            </geometry>
        </collision>
    </link>

    <joint name="Mani_J4" type="revolute">
        <origin xyz="-0.350 0.0 0.0" rpy="0.0 0.0 0.0"/>
        <parent link="Revlink3"/>
        <child link="Revlink4"/>
        <axis xyz="0 1 0"/>
        <limit effort="87" lower="-2.8973" upper="2.8973" velocity="2.1750"/>
        <dynamics damping="0.5" friction="0.2"/>
    </joint>

    <link name="Revlink5">
        <inertial>
            <mass value="0.1"/>
            <inertia ixx="0.1" ixy="0.0" ixz="0.0" 
                     iyy="0.1" iyz="0.0" izz="0.1"/>
        </inertial>
        <visual >
            <origin xyz="-0.04 0.0 0.0" rpy="0.0 1.57 0.0"/>
            <geometry name="Revlink5">
                <box size="0.080 0.080 0.050"/>
            </geometry>
        </visual>

          
        <collision>
            <origin xyz="-0.175 0.0 0.0" rpy="0.0 1.57 0.0"/>
            <geometry name="Revlink5">
                <box size="0.080 0.080 0.050"/>
            </geometry>
        </collision>
    </link>

    <joint name="Mani_J5" type="revolute">
        <origin xyz="-0.330 0.0 0.0" rpy="0.0 0.0 0.0"/>
        <parent link="Revlink4"/>
        <child link="Revlink5"/>
        <axis xyz="0 1 0"/>
        <limit effort="87" lower="-2.8973" upper="2.8973" velocity="2.1750"/>
        <dynamics damping="0.5" friction="0.2"/>
    </joint>

    <link name="Hand">
        <inertial>
            <mass value="0.05"/>
            <inertia ixx="0.4" ixy="0.0" ixz="0.0" 
                     iyy="0.4" iyz="0.0" izz="0.4"/>
        </inertial>
        <visual >
            <origin xyz="-0.050 0.0 0.0" rpy="0.0 0.0 0.0"/>
            <geometry name="Hand">
                <box size="0.100 0.160 0.095"/>
            </geometry>
        </visual>

        <collision>
            <origin xyz="-0.050 0.0 0.0" rpy="0.0 0.0 0.0"/>
            <geometry name="Hand">
                <box size="0.100 0.160 0.095"/>
                
            </geometry>
        </collision>
    </link>

    <joint name="Mani_J6" type="revolute">
        <origin xyz="-0.07 0.0 0.0" rpy="0.0 0.0 0.0"/>
        <parent link="Revlink5"/>
        <child link="Hand"/>
        <axis xyz="1 0 0"/>
        <limit effort="87" lower="-2.8973" upper="2.8973" velocity="2.1750"/>
        <dynamics damping="0.5" friction="0.2"/>
    </joint>

    <link name="FingerLeft">
        <inertial>
            <mass value="0.05"/>
            <inertia ixx="0.5" ixy="0.0" ixz="0.0" 
                     iyy="0.4" iyz="0.0" izz="0.5"/>
        </inertial>
        <visual>
            <origin xyz = "-0.080 0.0 0.0" rpy="0.0 0.0 0.0"/>
            <geometry name="FingerL">
                <box size="0.160 0.040 0.080"/>
            </geometry>
            <!-- <material name="Red"></material> -->
        </visual>
        <collision>
            <origin xyz = "-0.080 0.0 0.0" rpy="0.0 0.0 0.0"/>
            <geometry name="FingerL">
                <box size="0.160 0.040 0.080"/>
                
            </geometry>
        </collision>
    </link>

    <joint name="FingerL" type="fixed">
        <origin xyz="-0.03 -0.04 0.0" rpy="0.0 0.0 0.0"/>
        <parent link="Hand"/>
        <child link="FingerLeft"/>
        <axis xyz="0 0 1"/>
        <limit effort="87" lower="-2.8973" upper="2.8973" velocity="2.1750"/>
        <dynamics damping="0.5" friction="0.2"/>
    </joint>

    <link name="FingerRight">
        <inertial>
            <mass value="0.05"/>
            <inertia ixx="0.5" ixy="0.0" ixz="0.0" 
                     iyy="0.4" iyz="0.0" izz="0.5"/>
        </inertial>
        <visual>
            <origin xyz = "-0.080 0.0 0.0" rpy="0.0 0.0 0.0"/>
            <geometry name="FingerR">
                <box size="0.160 0.040 0.080"/>
            </geometry>
            <!-- <material name="Red"></material> -->
        </visual>
        <collision>
            <origin xyz = "-0.080 0.0 0.0" rpy="0.0 0.0 0.0"/>
            <geometry name="FingerR">
                <box size="0.160 0.040 0.080"/>
                
            </geometry>
        </collision>
    </link>

    <joint name="FingerR" type="fixed">
        <origin xyz="-0.03 0.04 0.0" rpy="0.0 0.0 0.0"/>
        <parent link="Hand"/>
        <child link="FingerRight"/>
        <axis xyz="0 0 1"/>
        <limit effort="87" lower="-2.8973" upper="2.8973" velocity="2.1750"/>
        <dynamics damping="0.5" friction="0.2"/>
    </joint>

    <link name="HandCamera">
        <inertial>
            <mass value="0.2"/>
            <inertia ixx="0.6" ixy="0.0" ixz="0.0" 
                     iyy="0.1" iyz="0.0" izz="0.1"/>
        </inertial>
        <visual name="Camera">
            <origin xyz="0.0 0.0 0.0" rpy="0.0 0.0 0.0"/>
            <geometry name = "Camera">
                <box size="0.03 0.08 0.03"/>
            </geometry>
            <!-- <material name="black"></material> -->
        </visual>
        <collision>
            <origin xyz="0.0 0.0 0.0" rpy="0.0 0.0 0.0"/>
            <geometry name = "Camera">
                <box size="0.03 0.08 0.03"/>
                
            </geometry>
        </collision>
    </link>

    <joint name="HandCam" type="fixed">
        <origin xyz="-0.02 0.0 0.065" rpy="0.0 0.0 0.0"/>
        <parent link="Hand"/>
        <child link="HandCamera"/>
    </joint> 

    <link name='rgb_cam_camera_link'>
		<visual>
			<origin xyz="0 0 0" rpy="0 0 0"/>
			<geometry>
				<box size="0.01 0.01 0.01"/>
			</geometry>
		</visual>
	</link>

    <joint name="rgb_cam_camera_link_joint" type="fixed">
		<origin rpy="0 0 0" xyz="0.04 0.0 0.2"/>
		<parent link="TorsolCamera"/>
		<child link="rgb_cam_camera_link"/>
	</joint>

    <link name="rgb_cam_camera_link_frame">
    </link>

    <joint name="rgb_cam_camera_frame_joint" type="fixed">
        <origin xyz="0.01 0 0" rpy="0 0 0" />
        <parent link="rgb_cam_camera_link" />
        <child link="rgb_cam_camera_link_frame" />
        <axis xyz="0 0 0"/>
     </joint>

    <link name='rgb_hand_cam_camera_link'>
		<visual>
			<origin xyz="0 0 0" rpy="0 0 0"/>
			<geometry>
				<box size="0.01 0.01 0.01"/>
			</geometry>
		</visual>
	</link>

    <joint name="rgb_hand_cam_camera_link_joint" type="fixed">
		<origin rpy="0 0 0" xyz="0.04 0.0 0.2"/>
		<parent link="HandCamera"/>
		<child link="rgb_hand_cam_camera_link"/>
	</joint>

    <link name="rgb_hand_cam_camera_link_frame">
    </link>

    <joint name="rgb_hand_cam_camera_frame_joint" type="fixed">
        <origin xyz="0.01 0 0" rpy="0 0 0" />
        <parent link="rgb_hand_cam_camera_link" />
        <child link="rgb_hand_cam_camera_link_frame" />
        <axis xyz="0 0 0"/>
     </joint>



</robot>
