<!-- <?xml version="1.0"?> -->


<robot name="mbse">
    
    <link name="mobilebaseI">
        <visual name="mobilebaseI">
            <origin xyz="0.0 0.0 0.080" rpy="0.0 0.0 0.0"/>
            <geometry name = "mobilebaseI">
                <box size="0.200 0.240 0.160"/>
            </geometry>
            <material name="white">
                <color rgba="1.0 1.0 1.0 1.0"/>
            </material>
        </visual>
        <inertial>
            <mass value="2.0"/>
            <inertia ixx="5.0" ixy="0.0" ixz="0.0" 
                     iyy="7.0" iyz="0.0" izz="6.0"/>
        </inertial>
        <collision>
            <origin xyz="0.0 0.0 0.080" rpy="0.0 0.0 0.0"/>
            <geometry name = "mobilebaseI">
                <box size="0.200 0.240 0.160"/>
                
            </geometry>
        </collision>
    </link>

    <link name="mobilebaseII">
        <visual name="mobilebaseII">
            <origin xyz="0.0 0.0 0.00" rpy="0.0 0.0 0.0"/>
            <geometry name = "mobilebaseII">
                <box size="0.270 0.400 0.100"/>
            </geometry>
            <material name="white">
            </material>
        </visual>
        <inertial>
            <mass value="18.0"/>
            <inertia ixx="8.0" ixy="0.0" ixz="0.0" 
                     iyy="2.0" iyz="0.0" izz="1.0"/>
        </inertial>
        <collision>
            <origin xyz="0.0 0.0 0.00" rpy="0.0 0.0 0.0"/>
            <geometry name = "mobilebaseII">
                <box size="0.270 0.400 0.100"/>
                
            </geometry>
        </collision>
    </link>

    <joint name="MobileBaseWheel" type="fixed">
        <origin xyz="0.235 0.0 0.110" rpy="0.0 0.0 0.0"/>
        <parent link="mobilebaseI"/>
        <child link="mobilebaseII"/>
    </joint>

    <link name="Wheel_Right">
        <inertial>
            <mass value="1.5"/>
            <inertia ixx="8.0" ixy="0.0" ixz="0.0" 
                     iyy="4.0" iyz="0.0" izz="4.0"/>
        </inertial>
        <visual name="Wheel">
            <origin xyz="0.0 0.0 0.0" rpy="0.0 0.0 0.0"/>
            <geometry name = "wheel">
                <cylinder radius="0.100" length="0.070"/>
            </geometry>
            <material name="Gray1">
                <color rgba="0.7 0.7 0.7 1.0"/>
            </material>
        </visual>
        <collision>
            <origin xyz="0.0 0.0 0.0" rpy="0.0 0.0 0.0"/>
            <geometry name = "wheel">
                <cylinder radius="0.100" length="0.070"/>
                
            </geometry>
        </collision>
    </link>

    <joint name="WheelR" type="continuous">
        <origin xyz="0.0 0.155 0.005" rpy="1.57 0.0 0.0"/>
        <parent link="mobilebaseI"/>
        <child link="Wheel_Right"/>
        <axis xyz="0.0 0.0 1.0"/>
        <limit effort="1000.0" velocity="10.0"/>
    </joint>

    <link name="Wheel_Left">
        <inertial>
            <mass value="1.5"/>
            <inertia ixx="8.0" ixy="0.0" ixz="0.0" 
                     iyy="4.0" iyz="0.0" izz="4.0"/>
        </inertial>
        <visual name="Wheel">
            <origin xyz="0.0 0.0 0.0" rpy="0.0 0.0 0.0"/>
            <geometry name = "wheel">
                <cylinder radius="0.100" length="0.070"/>
            </geometry>
            <material name="Gray1">
                <color rgba="0.7 0.7 0.7 1.0"/>
            </material>
        </visual>
        <collision>
            <origin xyz="0.0 0.0 0.0" rpy="0.0 0.0 0.0"/>
            <geometry name = "wheel">
                <cylinder radius="0.100" length="0.070"/>
                
            </geometry>
        </collision>
    </link>

    <joint name="WheelL" type="continuous">
        <origin xyz="0.0 -0.155 0.005" rpy="1.57 0.0 0.0"/>
        <parent link="mobilebaseI"/>
        <child link="Wheel_Left"/>
        <axis xyz="0.0 0.0 1.0"/>
        <limit effort="1000.0" velocity="10.0"/>
    </joint>

    <link name="CasterCase_Left">
        <inertial>
            <mass value="0.06"/>
            <inertia ixx="0.2" ixy="0.0" ixz="0.0" 
                     iyy="0.6" iyz="-0.7" izz="0.2"/>
        </inertial>
        <visual name="CasterCase">
            <origin xyz="0.0 0.0 -0.005" rpy="0.0 0.0 0.0"/>
            <geometry name = "CasterC">
                <cylinder radius="0.025" length="0.010"/>
            </geometry>
            <material name="Gray1">
                <color rgba="0.7 0.7 0.7 1.0"/>
            </material>
        </visual>
        <collision>
            <origin xyz="0.0 0.0 -0.005" rpy="0.0 0.0 0.0"/>
            <geometry name = "CasterC">
                <cylinder radius="0.025" length="0.010"/>
                
            </geometry>
        </collision>
    </link>

    <joint name="CasterCL" type="fixed">
        <origin xyz="0.040 -0.110 -0.05" rpy="0.0 0.0 0.0"/>
        <parent link="mobilebaseII"/>
        <child link="CasterCase_Left"/>
        <axis xyz="0.0 0.0 1.0"/>
    </joint>

    <link name="CasterWheel_Left">
        <inertial>
            <mass value="0.3"/>
            <inertia ixx="0.6" ixy="0.0" ixz="0.0" 
                     iyy="0.3" iyz="0.0" izz="0.3"/>
        </inertial>
        <visual name="CasterWheel">
            <origin xyz="0.0 0.0 0.0" rpy="0.0 0.0 0.0"/>
            <geometry name = "Casterwheel">
                <cylinder radius="0.0625" length="0.036"/>
            </geometry>
            <material name="Gray2">
                <color rgba="0.5 0.5 0.5 1.0"/>
            </material>
        </visual>
        <collision>
            <origin xyz="0.0 0.0 0.0" rpy="0.0 0.0 0.0"/>
            <geometry name = "Casterwheel">
                <cylinder radius="0.0625" length="0.036"/>
                
            </geometry>
        </collision>
    </link>

    <joint name="CasterWheelL" type="continuous">
        <origin xyz="0.0405 0.0 -0.0925" rpy="1.57 0.0 0.0"/>
        <parent link="CasterCase_Left"/>
        <child link="CasterWheel_Left"/>
        <axis xyz="0.0 0.0 1.0"/>
    </joint>

    <link name="CasterCase_Right">
        <inertial>
            <mass value="0.06"/>
            <inertia ixx="0.2" ixy="0.0" ixz="0.0" 
                     iyy="0.6" iyz="-0.7" izz="0.2"/>
        </inertial>
        <visual name="CasterCase">
            <origin xyz="0.0 0.0 -0.005" rpy="0.0 0.0 0.0"/>
            <geometry name = "CasterC">
                <cylinder radius="0.025" length="0.010"/>
            </geometry>
            <material name="Gray1">
                <color rgba="0.7 0.7 0.7 1.0"/>
            </material>
        </visual>
        <collision>
            <origin xyz="0.0 0.0 -0.005" rpy="0.0 0.0 0.0"/>
            <geometry name = "CasterC">
                <cylinder radius="0.025" length="0.010"/>
                
            </geometry>
        </collision>
    </link>

    <joint name="CasterCR" type="fixed">
        <origin xyz="0.040 0.110 -0.05" rpy="0.0 0.0 0.0"/>
        <parent link="mobilebaseII"/>
        <child link="CasterCase_Right"/>
        <axis xyz="1.0 0.0 0.0"/>
    </joint>

    <link name="CasterWheel_Right">
        <inertial>
            <mass value="0.3"/>
            <inertia ixx="0.6" ixy="0.0" ixz="0.0" 
                     iyy="0.3" iyz="0.0" izz="0.3"/>
        </inertial>
        <visual name="CasterWheel">
            <origin xyz="0.0 0.0 0.0" rpy="0.0 0.0 0.0"/>
            <geometry name = "Casterwheel">
                <cylinder radius="0.0625" length="0.036"/>
            </geometry>
            <material name="Gray2">
                <color rgba="0.5 0.5 0.5 1.0"/>
            </material>
        </visual>
        <collision>
            <origin xyz="0.0 0.0 0.0" rpy="0.0 0.0 0.0"/>
            <geometry name = "Casterwheel">
                <cylinder radius="0.0625" length="0.036"/>
                 
            </geometry>
        </collision>
    </link>

    <joint name="CasterWheelR" type="continuous">
        <origin xyz="0.0405 0.0 -0.0925" rpy="1.57 0.0 0.0"/>
        <parent link="CasterCase_Right"/>
        <child link="CasterWheel_Right"/>
        <axis xyz="0.0 0.0 1.0"/>
    </joint>

    <link name="mobilebaseIII">
        <inertial>
            <mass value="10.0"/>
            <inertia ixx="0.6" ixy="0.0" ixz="0.0" 
                     iyy="0.1" iyz="0.0" izz="0.4"/>
        </inertial>
        <visual name = "mobilebaseIII">
            <origin xyz="0.0 0.0 0.0" rpy="0.0 0.0 0.0"/>
            <geometry name = "mobilebaseIII">
                <box size="0.235 0.180 0.030"/>
            </geometry >
            <material name="white"></material>
        </visual>
        <collision>
            <origin xyz="0.0 0.0 0.0" rpy="0.0 0.0 0.0"/>
            <geometry name = "mobilebaseIII">
                <box size="0.235 0.180 0.030"/>
                
            </geometry >
        </collision>
    </link>

    <joint name="MobileBaseLidar" type="fixed">     
        <origin xyz="-0.100 0.0 0.065" rpy="0.0 0.0 0.0"/>
        <parent link="mobilebaseII"/>
        <child link="mobilebaseIII"/>
        <axis xyz="0.0 0.0 1.0"/>
    </joint>

    <link name="mobilebaseIV">
        <inertial>
            <mass value="1.0"/>
            <inertia ixx="0.2" ixy="0.0" ixz="0.0" 
                     iyy="0.3" iyz="0.0" izz="0.1"/>
        </inertial>
        <visual name = "mobilebaseIII">
            <origin xyz="0.0 0.0 0.0" rpy="0.0 0.0 0.0"/>
            <geometry name = "mobilebaseIV">
                <box size="0.470 0.400 0.045"/>
            </geometry >
            <material name="white"></material>
        </visual>
        <collision>
            <origin xyz="0.0 0.0 0.0" rpy="0.0 0.0 0.0"/>
            <geometry name = "mobilebaseIV">
                <box size="0.470 0.400 0.045"/>
                
            </geometry >
        </collision>
    </link>

    <joint name="MobileBaseTorsol" type="fixed">
        <origin xyz="0.0 0.0 0.0375" rpy="0.0 0.0 0.0"/>
        <parent link="mobilebaseIII"/>
        <child link="mobilebaseIV"/>
    </joint>

    <link name="Lidar_Front">
        <inertial>
            <mass value="0.3"/>
            <inertia ixx="0.4" ixy="0.0" ixz="0.0" 
                     iyy="0.7" iyz="0.0" izz="0.4"/>
        </inertial>
        <visual name="Lidar_Front">
            <origin xyz="0.0 0.0 0.0" rpy="0.0 0.0 0.0"/>
            <geometry name = "Lidar_front">
                <cylinder radius="0.035" length="0.030"/>
            </geometry>
            <material name="Gray4">
                <color rgba="0.2 0.2 0.2 1.0"/>
            </material>
        </visual>
        <collision>
            <origin xyz="0.0 0.0 0.0" rpy="0.0 0.0 0.0"/>
            <geometry name = "Lidar_front">
                <cylinder radius="0.035" length="0.030"/>
            </geometry>
        </collision>
    </link>

    <joint name="LidarF" type="fixed">
        <origin xyz="-0.178 0.150 0.075" rpy="0.0 0.0 0.0"/>
        <parent link="mobilebaseIII"/>
        <child link="Lidar_Front"/>
        <axis xyz="1.0 0.0 0.0"/>
    </joint>

    <link name="Lidar_Back">
        <inertial>
            <mass value="0.3"/>
            <inertia ixx="0.4" ixy="0.0" ixz="0.0" 
                     iyy="0.7" iyz="0.0" izz="0.4"/>
        </inertial>
        <visual name="Lidar_Back">
            <origin xyz="0.0 0.0 0.0" rpy="0.0 0.0 0.0"/>
            <geometry name = "Lidar_back">
                <cylinder radius="0.035" length="0.030"/>
            </geometry>
            <material name="Gray4">
                <color rgba="0.2 0.2 0.2 1.0"/>
            </material>
        </visual>
        <collision>
            <origin xyz="0.0 0.0 0.0" rpy="0.0 0.0 0.0"/>
            <geometry name = "Lidar_back">
                <cylinder radius="0.035" length="0.030"/>
                
            </geometry>
        </collision>
    </link>

    <joint name="LidarB" type="fixed">
        <origin xyz="0.178 -0.150 0.0" rpy="0.0 0.0 0.0"/>
        <parent link="mobilebaseIII"/>
        <child link="Lidar_Back"/>
      
    </joint>

    <link name="Torsol">
        <inertial>
            <mass value="0.8"/>
            <inertia ixx="7.0" ixy="5.0" ixz="8.0" 
                     iyy="4.0" iyz="4.0" izz="7.0"/>
        </inertial>
        <visual name="Body">
            <origin xyz="0.0 0.0 0.445" rpy="0.0 0.0 0.0"/>
            <geometry name = "body">
                <box size="0.220 0.285 0.890"/>
            </geometry>
            <material name="white"></material>
        </visual>
        <collision>
            <origin xyz="0.0 0.0 0.445" rpy="0.0 0.0 0.0"/>
            <geometry name = "body">
                <box size="0.220 0.285 0.890"/>
                
            </geometry>
        </collision>
    </link>

    <joint name="BaseTorsol" type="fixed">
        <origin xyz="0.125 -0.0575 0.0225" rpy="0.0 0.0 0.0"/>
        <parent link="mobilebaseIV"/>
        <child link="Torsol"/>
    </joint>

    <link name="TorsolCamera">
        <inertial>
            <origin xyz="0.0 1.0 0.0" rpy="0.0 0.0 0.0"/>
            <mass value="0.2"/>
            <inertia ixx="0.6" ixy="0.0" ixz="0.0" 
                     iyy="0.1" iyz="0.0" izz="0.1"/>
        </inertial>
        <visual>
            <origin xyz="0.0 0.0 0.0" rpy="0.0 0.0 0.0"/>
            <geometry name = "Camera">
                <box size="0.03 0.08 0.03"/>
            </geometry>
            <material name="black">
                <color rgba="0.0 0.0 0.0 0.5"/>
            </material>
        </visual>
        <collision>
            <origin xyz="0.0 1.0 0.0" rpy="0.0 0.0 0.0"/>
            <geometry name = "Camera">
                <box size="0.03 0.08 0.03"/>
            </geometry>
        </collision>
    </link>

    <joint name="BodyCam" type="revolute">
        <origin xyz="-0.05 0.182 0.85" rpy="0.0 0.0 0.0"/>
        <parent link="Torsol"/>
        <child link="TorsolCamera"/>
        <axis xyz="0.0 1.0 0.0"/>
        <limit effort="1000.0" lower="-1.5" upper="1.5" velocity="0.5"/>
       
    </joint>



    <link name="LinearJoint">
        <inertial>
            <mass value="0.5"/>
            <inertia ixx="7.0" ixy="-5.0" ixz="8.0" 
                     iyy="4.0" iyz="4.0" izz="7.0"/>
        </inertial>
        <visual>
            <origin xyz="0.0 0.0 0.0" rpy="0.0 0.0 0.0"/>
            <geometry name = "LinearJ">
                <cylinder radius="0.080" length="0.050"/>
            </geometry>
            <material name="Red">
                <color rgba="1.0 0.0 0.0 1.0"/>
            </material>
        </visual>
        <collision>
            <origin xyz="0.0 0.0 0.0" rpy="0.0 0.0 0.0"/>
            <geometry name = "LinearJ">
                <cylinder radius="0.080" length="0.050"/>
                
            </geometry>
        </collision>
    </link>

    <joint name="LinJ" type="prismatic">
        <origin xyz="-0.17 0.0 0.0275" rpy="0.0 0.0 0.0"/>
        <parent link="Torsol"/>
        <child link="LinearJoint"/>
        <axis xyz="0.0 0.0 1.0"/>
        <limit lower="0.0" upper="0.650" effort="1000.0" velocity="10.0"/>
    </joint>

    <link name="Revlink1">
        <inertial>
            <mass value="0.1"/>
            <inertia ixx="0.4" ixy="0.0" ixz="0.0" 
                     iyy="0.4" iyz="0.7" izz="0.1"/>
        </inertial>
        <visual >
            <origin xyz="0.0 0.0 -0.050" rpy="0.0 0.0 0.0"/>
            <geometry name="RevL1">
                <box size="0.080 0.080 0.100"/>
            </geometry>
            <material name="Orange">
                <color rgba="1.0 0.5 0.0 1.0"/>
            </material>
        </visual>
        <collision>
            <origin xyz="0.0 0.0 -0.050" rpy="0.0 0.0 0.0"/>
            <geometry name="RevL1">
                <box size="0.080 0.080 0.100"/>
               
            </geometry>
        </collision>
    </link>

    <joint name="RevJ1" type="revolute">
        <origin xyz="0.0 0.0 0.125" rpy="0.0 0.0 3.14"/>
        <parent link="LinearJoint"/>
        <child link="Revlink1"/>
        <axis xyz="0.0 0.0 1.0"/>
        <limit effort="1000.0" lower="-1.3" upper="1.3" velocity="0.5"/>
        
    </joint>

    <link name="Revlink2">
        <inertial>
            <mass value="0.1"/>
            <inertia ixx="0.9" ixy="0.0" ixz="0.0" 
                     iyy="0.4" iyz="0.0" izz="0.9"/>
        </inertial>
        <visual >
            <origin xyz="0.0 0.0 -0.050" rpy="0.0 0.0 0.0"/>
            <geometry name="RevL2">
                <box size="0.080 0.080 0.100"/>
            </geometry>
            <material name="Yellow">
                <color rgba="1.0 1.0 0.0 1.0"/>
            </material>
        </visual>
        <collision>
            <origin xyz="0.0 0.0 -0.050" rpy="0.0 0.0 0.0"/>
            <geometry name="RevL2">
                <box size="0.080 0.080 0.100"/>
                
            </geometry>
        </collision>
    </link>

    <joint name="RevJ2" type="revolute">
        <origin xyz="0.06 0.0 0.05" rpy="0.0 1.57 0.0"/>
        <parent link="Revlink1"/>
        <child link="Revlink2"/>
        <axis xyz="0.0 0.0 1.0"/>
        <limit effort="1000.0" lower="-1.5" upper="1.5" velocity="0.5"/>
       
    </joint>

    <link name="Revlink3">
        <inertial>
            <mass value="0.1"/>
            <inertia ixx="0.9" ixy="0.0" ixz="0.0" 
                     iyy="0.1" iyz="0.5" izz="0.8"/>
        </inertial>
        <visual >
            <origin xyz="-0.175 0.0 0.0" rpy="0.0 1.57 0.0"/>
            <geometry name="RevL3">
                <box size="0.080 0.080 0.350"/>
            </geometry>
            <material name="Green">
                <color rgba="0.0 1.0 0.0 1.0"/>
            </material>
        </visual>
        <collision>
            <origin xyz="-0.175 0.0 0.0" rpy="0.0 1.57 0.0"/>
            <geometry name="RevL3">
                <box size="0.080 0.080 0.350"/>
            </geometry>
        </collision>
    </link>

    <joint name="RevJ3" type="revolute">
        <origin xyz="0.0 0.0 0.0" rpy="1.57 1.57 0.0"/>
        <parent link="Revlink2"/>
        <child link="Revlink3"/>
        <axis xyz="0.0 0.0 1.0"/>
        <limit effort="1000.0" lower="-1.2" upper="2.0" velocity="0.5"/>
      
    </joint>

    <link name="Revlink4">
        <inertial>
            <mass value="0.1"/>
            <inertia ixx="0.9" ixy="0.0" ixz="0.0" 
                     iyy="0.1" iyz="0.5" izz="0.8"/>
        </inertial>
        <visual >
            <origin xyz="-0.175 0.0 0.0" rpy="0.0 1.57 0.0"/>
            <geometry name="RevL4">
                <box size="0.080 0.080 0.350"/>
            </geometry>
            <material name="Blue">
                <color rgba="0.0 0.0 1.0 1.0"/>
            </material>
        </visual>
        <collision>
            <origin xyz="-0.175 0.0 0.0" rpy="0.0 1.57 0.0"/>
            <geometry name="RevL4">
                <box size="0.080 0.080 0.350"/>
                
            </geometry>
        </collision>
    </link>

    <joint name="RevJ4" type="revolute">
        <origin xyz="-0.350 0.0 0.0" rpy="0.0 0.0 0.0"/>
        <parent link="Revlink3"/>
        <child link="Revlink4"/>
        <axis xyz="0.0 0.0 1.0"/>
        <limit effort="1000.0" lower="-1.9" upper="1.9" velocity="0.5"/>
      
    </joint>

    <link name="Revlink5">
        <inertial>
            <mass value="0.1"/>
            <inertia ixx="0.1" ixy="0.0" ixz="0.0" 
                     iyy="0.1" iyz="0.0" izz="0.1"/>
        </inertial>
        <visual >
            <origin xyz="-0.04 0.0 0.0" rpy="0.0 1.57 0.0"/>
            <geometry name="RevL5">
                <box size="0.080 0.080 0.050"/>
            </geometry>
            <material name="Purple">
                <color rgba="0.5 0.0 1.0 1.0"/>
            </material>
        </visual>
        <collision>
            <origin xyz="-0.04 0.0 0.0" rpy="0.0 1.57 0.0"/>
            <geometry name="RevL5">
                <box size="0.080 0.080 0.050"/>
                
            </geometry>
        </collision>
    </link>

    <joint name="RevJ5" type="revolute">
        <origin xyz="-0.331 0.0 -0.0" rpy="0.0 0.0 0.0"/>
        <parent link="Revlink4"/>
        <child link="Revlink5"/>
        <axis xyz="0.0 0.0 1.0"/>
        <limit effort="1000.0" lower="-3.14" upper="3.14" velocity="0.5"/>
    </joint>

    <link name="Hand">
        <inertial>
            <mass value="0.05"/>
            <inertia ixx="0.4" ixy="0.0" ixz="0.0" 
                     iyy="0.4" iyz="0.0" izz="0.4"/>
        </inertial>
        <visual >
            <origin xyz="-0.0 0.0 0.0475" rpy="0.0 1.57 0.0"/>
            <geometry name="Hand">
                <box size="0.100 0.160 0.095"/>
            </geometry>
            <material name="white"></material>
        </visual>
        <collision>
            <origin xyz="-0.0 0.0 0.0475" rpy="0.0 1.57 0.0"/>
            <geometry name="Hand">
                <box size="0.100 0.160 0.095"/>
                
            </geometry>
        </collision>
    </link>

    <joint name="HandGripper" type="revolute">
        <origin xyz="-0.05 -0.0 -0.0" rpy="0.0 -1.57 0.0"/>
        <parent link="Revlink5"/>
        <child link="Hand"/>
        <axis xyz="0.0 0.0 1.0"/>
        <limit effort="1000.0" lower="-3.14" upper="3.14" velocity="0.5"/>
        
    </joint>

    <link name="FingerLeft">
        <inertial>
            <mass value="0.05"/>
            <inertia ixx="0.5" ixy="0.0" ixz="0.0" 
                     iyy="0.4" iyz="0.0" izz="0.5"/>
        </inertial>
        <visual>
            <origin xyz = "-0.080 0.0 0.0" rpy="0.0 0.0 0.0"/>
            <geometry name="FingerL">
                <box size="0.160 0.040 0.080"/>
            </geometry>
            <material name="Red"></material>
        </visual>
        <collision>
            <origin xyz = "-0.080 0.0 0.0" rpy="0.0 0.0 0.0"/>
            <geometry name="FingerL">
                <box size="0.160 0.040 0.080"/>
                
            </geometry>
        </collision>
    </link>

    <joint name="FingerL" type="prismatic">
        <origin xyz="-0.0 -0.06 0.1" rpy="0.0 1.57 0.0"/>
        <parent link="Hand"/>
        <child link="FingerLeft"/>
        <axis xyz="0.0 0.1 0.0"/>
        <limit effort="1000.0" lower="-0.02" upper="0.1" velocity="0.5"/>
    </joint>

    <link name="FingerRight">
        <inertial>
            <mass value="0.05"/>
            <inertia ixx="0.5" ixy="0.0" ixz="0.0" 
                     iyy="0.4" iyz="0.0" izz="0.5"/>
        </inertial>
        <visual>
            <origin xyz = "-0.080 0.0 0.0" rpy="0.0 0.0 0.0"/>
            <geometry name="FingerR">
                <box size="0.160 0.040 0.080"/>
            </geometry>
            <material name="Red"></material>
        </visual>
        <collision>
            <origin xyz = "-0.080 0.0 0.0" rpy="0.0 0.0 0.0"/>
            <geometry name="FingerR">
                <box size="0.160 0.040 0.080"/>
                
            </geometry>
        </collision>
    </link>

    <joint name="FingerR" type="prismatic">
        <origin xyz="-0.0 0.06 0.1" rpy="0.0 1.57 0.0"/>
        <parent link="Hand"/>
        <child link="FingerRight"/>
        <axis xyz="0.0 1.0 0.0"/>
        <limit effort="1000.0" lower="-0.1" upper="0.02" velocity="0.5"/>
    </joint>

    <link name="HandCamera">
        <inertial>
            <mass value="0.2"/>
            <inertia ixx="0.6" ixy="0.0" ixz="0.0" 
                     iyy="0.1" iyz="0.0" izz="0.1"/>
        </inertial>
        <visual name="Camera">
            <origin xyz="0.0 0.0 0.0" rpy="0.0 0.0 0.0"/>
            <geometry name = "Camera">
                <box size="0.03 0.08 0.03"/>
            </geometry>
            <material name="black">
                <color rgba="0.0 0.0 0.0 0.5"/>
            </material>
        </visual>
        <collision>
            <origin xyz="0.0 0.0 0.0" rpy="0.0 0.0 0.0"/>
            <geometry name = "Camera">
                <box size="0.03 0.08 0.03"/>
                
            </geometry>
        </collision>
    </link>

    <joint name="HandCam" type="fixed">
        <origin xyz="-0.0625 0.0 0.03" rpy="0.0 0.0 0.0"/>
        <parent link="Hand"/>
        <child link="HandCamera"/>
    </joint> 

</robot>
